Workbook

Sheet Instructions
A1: MSL AI Skills training platform — competitive benchmark
A2: Thematica AI LLC · prepared for Dr. Abdulai Jawo Bah · October 2026
A4: Purpose | B4: Benchmark the planned MSL AI Skills training platform (hands-on AI upskilling for US Medical Science Liaisons: prompting → workflows → vibe coding → agents → automation, compliance-embedded, certified) against the players that sell AI training to MSLs and medical affairs today.
A5: How to use | B5: Read Summary for the ranking and gate failures, Gap analysis for the white space, Roadmap ceiling for what the product can realistically earn by phase. Change a score or weight on Rubric or Summary and every sheet recalculates.
A6: Cells to edit (yellow only) | B6: Rubric: weights, gate flags and scores. Summary: domain weights. Viability: scores. Roadmap ceiling: phase scores. Blue text = input. Everything else is formula.
A7: Score 0 / 1 / 2 / 3 | B7: 0 = absent or no evidence found. 1 = mentioned or minimal. 2 = partial, real but incomplete. 3 = matches 'What a 3 looks like' on Rubric.
A8: Criterion weight | B8: 1 = useful, 2 = important, 3 = critical.
A9: Domain weight (must total 100%) | B9: Set on Summary. Weight check shows OK only when the ten domain weights total 100%.
A10: Gate criteria | B10: D1.1 anchored to real MSL tasks; D3.1 non-promotional/off-label/PhRMA guardrails; D3.2 data governance (PHI, embargoed data, sanctioned tools); D3.3 pharmacovigilance AE routing; D5.1 performance-based assessment. A gate below 2 is a gate failure whatever the total.
A11: Domain score | B11: Sum of (criterion weight × score) ÷ (sum of criterion weights × 3) for criteria in that domain. Overall = domain scores weighted by domain weights.
A12: Evidence standard | B12: Competitor scores come only from public pages opened in October 2026 (course pages, pricing, privacy/trust pages, press). No evidence = 0 or 1, noted 'no evidence found'. A low score can mean 'not documented', not 'cannot do'.
A13: How MSL AI Skills was scored | B13: It does not exist yet: no live site, course or pilot. It is entered as a DESIGN TARGET (all 3s) taken from the founder's meta-prompt (Aug 2026). It is not ranked and must not be presented as an evidence-based score. Roadmap ceiling gives a realistic per-phase estimate instead.
A14: Bias note | B14: The rubric was written by the same reviewer who scored the product's targets, and it is shaped around the product's intended white space. Competitors built for other jobs (Inizio rehearsal, Section horizontal) score low by design of the rubric. Get an outside re-score, ideally by a medical-affairs L&D buyer, before any public use.

Sheet Summary
A1: Summary — weighted scores by domain
A2: Domain score = weighted criterion scores ÷ (weights × 3). The design-target column is not ranked. Edit domain weights (yellow); they must total 100%.
A4: Domain | B4: Domain weight | C4: =Rubric!G4 | D4: =Rubric!H4 | E4: =Rubric!I4 | F4: =Rubric!J4 | G4: =Rubric!K4 | H4: =Rubric!L4 | I4: =Rubric!M4 | J4: =Rubric!N4 | K4: =Rubric!O4
A5: MSL role specificity | B5: 0.1 | C5: =IFERROR(SUMPRODUCT((Rubric!$B$5:$B$46=$A5)*Rubric!$E$5:$E$46*Rubric!G$5:G$46)/(SUMPRODUCT((Rubric!$B$5:$B$46=$A5)*Rubric!$E$5:$E$46)*3),0) | D5: =IFERROR(SUMPRODUCT((Rubric!$B$5:$B$46=$A5)*Rubric!$E$5:$E$46*Rubric!H$5:H$46)/(SUMPRODUCT((Rubric!$B$5:$B$46=$A5)*Rubric!$E$5:$E$46)*3),0) | E5: =IFERROR(SUMPRODUCT((Rubric!$B$5:$B$46=$A5)*Rubric!$E$5:$E$46*Rubric!I$5:I$46)/(SUMPRODUCT((Rubric!$B$5:$B$46=$A5)*Rubric!$E$5:$E$46)*3),0) | F5: =IFERROR(SUMPRODUCT((Rubric!$B$5:$B$46=$A5)*Rubric!$E$5:$E$46*Rubric!J$5:J$46)/(SUMPRODUCT((Rubric!$B$5:$B$46=$A5)*Rubric!$E$5:$E$46)*3),0) | G5: =IFERROR(SUMPRODUCT((Rubric!$B$5:$B$46=$A5)*Rubric!$E$5:$E$46*Rubric!K$5:K$46)/(SUMPRODUCT((Rubric!$B$5:$B$46=$A5)*Rubric!$E$5:$E$46)*3),0) | H5: =IFERROR(SUMPRODUCT((Rubric!$B$5:$B$46=$A5)*Rubric!$E$5:$E$46*Rubric!L$5:L$46)/(SUMPRODUCT((Rubric!$B$5:$B$46=$A5)*Rubric!$E$5:$E$46)*3),0) | I5: =IFERROR(SUMPRODUCT((Rubric!$B$5:$B$46=$A5)*Rubric!$E$5:$E$46*Rubric!M$5:M$46)/(SUMPRODUCT((Rubric!$B$5:$B$46=$A5)*Rubric!$E$5:$E$46)*3),0) | J5: =IFERROR(SUMPRODUCT((Rubric!$B$5:$B$46=$A5)*Rubric!$E$5:$E$46*Rubric!N$5:N$46)/(SUMPRODUCT((Rubric!$B$5:$B$46=$A5)*Rubric!$E$5:$E$46)*3),0) | K5: =IFERROR(SUMPRODUCT((Rubric!$B$5:$B$46=$A5)*Rubric!$E$5:$E$46*Rubric!O$5:O$46)/(SUMPRODUCT((Rubric!$B$5:$B$46=$A5)*Rubric!$E$5:$E$46)*3),0)
A6: Hands-on depth across the AI stack | B6: 0.14 | C6: =IFERROR(SUMPRODUCT((Rubric!$B$5:$B$46=$A6)*Rubric!$E$5:$E$46*Rubric!G$5:G$46)/(SUMPRODUCT((Rubric!$B$5:$B$46=$A6)*Rubric!$E$5:$E$46)*3),0) | D6: =IFERROR(SUMPRODUCT((Rubric!$B$5:$B$46=$A6)*Rubric!$E$5:$E$46*Rubric!H$5:H$46)/(SUMPRODUCT((Rubric!$B$5:$B$46=$A6)*Rubric!$E$5:$E$46)*3),0) | E6: =IFERROR(SUMPRODUCT((Rubric!$B$5:$B$46=$A6)*Rubric!$E$5:$E$46*Rubric!I$5:I$46)/(SUMPRODUCT((Rubric!$B$5:$B$46=$A6)*Rubric!$E$5:$E$46)*3),0) | F6: =IFERROR(SUMPRODUCT((Rubric!$B$5:$B$46=$A6)*Rubric!$E$5:$E$46*Rubric!J$5:J$46)/(SUMPRODUCT((Rubric!$B$5:$B$46=$A6)*Rubric!$E$5:$E$46)*3),0) | G6: =IFERROR(SUMPRODUCT((Rubric!$B$5:$B$46=$A6)*Rubric!$E$5:$E$46*Rubric!K$5:K$46)/(SUMPRODUCT((Rubric!$B$5:$B$46=$A6)*Rubric!$E$5:$E$46)*3),0) | H6: =IFERROR(SUMPRODUCT((Rubric!$B$5:$B$46=$A6)*Rubric!$E$5:$E$46*Rubric!L$5:L$46)/(SUMPRODUCT((Rubric!$B$5:$B$46=$A6)*Rubric!$E$5:$E$46)*3),0) | I6: =IFERROR(SUMPRODUCT((Rubric!$B$5:$B$46=$A6)*Rubric!$E$5:$E$46*Rubric!M$5:M$46)/(SUMPRODUCT((Rubric!$B$5:$B$46=$A6)*Rubric!$E$5:$E$46)*3),0) | J6: =IFERROR(SUMPRODUCT((Rubric!$B$5:$B$46=$A6)*Rubric!$E$5:$E$46*Rubric!N$5:N$46)/(SUMPRODUCT((Rubric!$B$5:$B$46=$A6)*Rubric!$E$5:$E$46)*3),0) | K6: =IFERROR(SUMPRODUCT((Rubric!$B$5:$B$46=$A6)*Rubric!$E$5:$E$46*Rubric!O$5:O$46)/(SUMPRODUCT((Rubric!$B$5:$B$46=$A6)*Rubric!$E$5:$E$46)*3),0)
A7: Compliance embedded | B7: 0.14 | C7: =IFERROR(SUMPRODUCT((Rubric!$B$5:$B$46=$A7)*Rubric!$E$5:$E$46*Rubric!G$5:G$46)/(SUMPRODUCT((Rubric!$B$5:$B$46=$A7)*Rubric!$E$5:$E$46)*3),0) | D7: =IFERROR(SUMPRODUCT((Rubric!$B$5:$B$46=$A7)*Rubric!$E$5:$E$46*Rubric!H$5:H$46)/(SUMPRODUCT((Rubric!$B$5:$B$46=$A7)*Rubric!$E$5:$E$46)*3),0) | E7: =IFERROR(SUMPRODUCT((Rubric!$B$5:$B$46=$A7)*Rubric!$E$5:$E$46*Rubric!I$5:I$46)/(SUMPRODUCT((Rubric!$B$5:$B$46=$A7)*Rubric!$E$5:$E$46)*3),0) | F7: =IFERROR(SUMPRODUCT((Rubric!$B$5:$B$46=$A7)*Rubric!$E$5:$E$46*Rubric!J$5:J$46)/(SUMPRODUCT((Rubric!$B$5:$B$46=$A7)*Rubric!$E$5:$E$46)*3),0) | G7: =IFERROR(SUMPRODUCT((Rubric!$B$5:$B$46=$A7)*Rubric!$E$5:$E$46*Rubric!K$5:K$46)/(SUMPRODUCT((Rubric!$B$5:$B$46=$A7)*Rubric!$E$5:$E$46)*3),0) | H7: =IFERROR(SUMPRODUCT((Rubric!$B$5:$B$46=$A7)*Rubric!$E$5:$E$46*Rubric!L$5:L$46)/(SUMPRODUCT((Rubric!$B$5:$B$46=$A7)*Rubric!$E$5:$E$46)*3),0) | I7: =IFERROR(SUMPRODUCT((Rubric!$B$5:$B$46=$A7)*Rubric!$E$5:$E$46*Rubric!M$5:M$46)/(SUMPRODUCT((Rubric!$B$5:$B$46=$A7)*Rubric!$E$5:$E$46)*3),0) | J7: =IFERROR(SUMPRODUCT((Rubric!$B$5:$B$46=$A7)*Rubric!$E$5:$E$46*Rubric!N$5:N$46)/(SUMPRODUCT((Rubric!$B$5:$B$46=$A7)*Rubric!$E$5:$E$46)*3),0) | K7: =IFERROR(SUMPRODUCT((Rubric!$B$5:$B$46=$A7)*Rubric!$E$5:$E$46*Rubric!O$5:O$46)/(SUMPRODUCT((Rubric!$B$5:$B$46=$A7)*Rubric!$E$5:$E$46)*3),0)
A8: Learning design for a field schedule | B8: 0.1 | C8: =IFERROR(SUMPRODUCT((Rubric!$B$5:$B$46=$A8)*Rubric!$E$5:$E$46*Rubric!G$5:G$46)/(SUMPRODUCT((Rubric!$B$5:$B$46=$A8)*Rubric!$E$5:$E$46)*3),0) | D8: =IFERROR(SUMPRODUCT((Rubric!$B$5:$B$46=$A8)*Rubric!$E$5:$E$46*Rubric!H$5:H$46)/(SUMPRODUCT((Rubric!$B$5:$B$46=$A8)*Rubric!$E$5:$E$46)*3),0) | E8: =IFERROR(SUMPRODUCT((Rubric!$B$5:$B$46=$A8)*Rubric!$E$5:$E$46*Rubric!I$5:I$46)/(SUMPRODUCT((Rubric!$B$5:$B$46=$A8)*Rubric!$E$5:$E$46)*3),0) | F8: =IFERROR(SUMPRODUCT((Rubric!$B$5:$B$46=$A8)*Rubric!$E$5:$E$46*Rubric!J$5:J$46)/(SUMPRODUCT((Rubric!$B$5:$B$46=$A8)*Rubric!$E$5:$E$46)*3),0) | G8: =IFERROR(SUMPRODUCT((Rubric!$B$5:$B$46=$A8)*Rubric!$E$5:$E$46*Rubric!K$5:K$46)/(SUMPRODUCT((Rubric!$B$5:$B$46=$A8)*Rubric!$E$5:$E$46)*3),0) | H8: =IFERROR(SUMPRODUCT((Rubric!$B$5:$B$46=$A8)*Rubric!$E$5:$E$46*Rubric!L$5:L$46)/(SUMPRODUCT((Rubric!$B$5:$B$46=$A8)*Rubric!$E$5:$E$46)*3),0) | I8: =IFERROR(SUMPRODUCT((Rubric!$B$5:$B$46=$A8)*Rubric!$E$5:$E$46*Rubric!M$5:M$46)/(SUMPRODUCT((Rubric!$B$5:$B$46=$A8)*Rubric!$E$5:$E$46)*3),0) | J8: =IFERROR(SUMPRODUCT((Rubric!$B$5:$B$46=$A8)*Rubric!$E$5:$E$46*Rubric!N$5:N$46)/(SUMPRODUCT((Rubric!$B$5:$B$46=$A8)*Rubric!$E$5:$E$46)*3),0) | K8: =IFERROR(SUMPRODUCT((Rubric!$B$5:$B$46=$A8)*Rubric!$E$5:$E$46*Rubric!O$5:O$46)/(SUMPRODUCT((Rubric!$B$5:$B$46=$A8)*Rubric!$E$5:$E$46)*3),0)
A9: Assessment and credential | B9: 0.12 | C9: =IFERROR(SUMPRODUCT((Rubric!$B$5:$B$46=$A9)*Rubric!$E$5:$E$46*Rubric!G$5:G$46)/(SUMPRODUCT((Rubric!$B$5:$B$46=$A9)*Rubric!$E$5:$E$46)*3),0) | D9: =IFERROR(SUMPRODUCT((Rubric!$B$5:$B$46=$A9)*Rubric!$E$5:$E$46*Rubric!H$5:H$46)/(SUMPRODUCT((Rubric!$B$5:$B$46=$A9)*Rubric!$E$5:$E$46)*3),0) | E9: =IFERROR(SUMPRODUCT((Rubric!$B$5:$B$46=$A9)*Rubric!$E$5:$E$46*Rubric!I$5:I$46)/(SUMPRODUCT((Rubric!$B$5:$B$46=$A9)*Rubric!$E$5:$E$46)*3),0) | F9: =IFERROR(SUMPRODUCT((Rubric!$B$5:$B$46=$A9)*Rubric!$E$5:$E$46*Rubric!J$5:J$46)/(SUMPRODUCT((Rubric!$B$5:$B$46=$A9)*Rubric!$E$5:$E$46)*3),0) | G9: =IFERROR(SUMPRODUCT((Rubric!$B$5:$B$46=$A9)*Rubric!$E$5:$E$46*Rubric!K$5:K$46)/(SUMPRODUCT((Rubric!$B$5:$B$46=$A9)*Rubric!$E$5:$E$46)*3),0) | H9: =IFERROR(SUMPRODUCT((Rubric!$B$5:$B$46=$A9)*Rubric!$E$5:$E$46*Rubric!L$5:L$46)/(SUMPRODUCT((Rubric!$B$5:$B$46=$A9)*Rubric!$E$5:$E$46)*3),0) | I9: =IFERROR(SUMPRODUCT((Rubric!$B$5:$B$46=$A9)*Rubric!$E$5:$E$46*Rubric!M$5:M$46)/(SUMPRODUCT((Rubric!$B$5:$B$46=$A9)*Rubric!$E$5:$E$46)*3),0) | J9: =IFERROR(SUMPRODUCT((Rubric!$B$5:$B$46=$A9)*Rubric!$E$5:$E$46*Rubric!N$5:N$46)/(SUMPRODUCT((Rubric!$B$5:$B$46=$A9)*Rubric!$E$5:$E$46)*3),0) | K9: =IFERROR(SUMPRODUCT((Rubric!$B$5:$B$46=$A9)*Rubric!$E$5:$E$46*Rubric!O$5:O$46)/(SUMPRODUCT((Rubric!$B$5:$B$46=$A9)*Rubric!$E$5:$E$46)*3),0)
A10: Outcomes and measurement | B10: 0.08 | C10: =IFERROR(SUMPRODUCT((Rubric!$B$5:$B$46=$A10)*Rubric!$E$5:$E$46*Rubric!G$5:G$46)/(SUMPRODUCT((Rubric!$B$5:$B$46=$A10)*Rubric!$E$5:$E$46)*3),0) | D10: =IFERROR(SUMPRODUCT((Rubric!$B$5:$B$46=$A10)*Rubric!$E$5:$E$46*Rubric!H$5:H$46)/(SUMPRODUCT((Rubric!$B$5:$B$46=$A10)*Rubric!$E$5:$E$46)*3),0) | E10: =IFERROR(SUMPRODUCT((Rubric!$B$5:$B$46=$A10)*Rubric!$E$5:$E$46*Rubric!I$5:I$46)/(SUMPRODUCT((Rubric!$B$5:$B$46=$A10)*Rubric!$E$5:$E$46)*3),0) | F10: =IFERROR(SUMPRODUCT((Rubric!$B$5:$B$46=$A10)*Rubric!$E$5:$E$46*Rubric!J$5:J$46)/(SUMPRODUCT((Rubric!$B$5:$B$46=$A10)*Rubric!$E$5:$E$46)*3),0) | G10: =IFERROR(SUMPRODUCT((Rubric!$B$5:$B$46=$A10)*Rubric!$E$5:$E$46*Rubric!K$5:K$46)/(SUMPRODUCT((Rubric!$B$5:$B$46=$A10)*Rubric!$E$5:$E$46)*3),0) | H10: =IFERROR(SUMPRODUCT((Rubric!$B$5:$B$46=$A10)*Rubric!$E$5:$E$46*Rubric!L$5:L$46)/(SUMPRODUCT((Rubric!$B$5:$B$46=$A10)*Rubric!$E$5:$E$46)*3),0) | I10: =IFERROR(SUMPRODUCT((Rubric!$B$5:$B$46=$A10)*Rubric!$E$5:$E$46*Rubric!M$5:M$46)/(SUMPRODUCT((Rubric!$B$5:$B$46=$A10)*Rubric!$E$5:$E$46)*3),0) | J10: =IFERROR(SUMPRODUCT((Rubric!$B$5:$B$46=$A10)*Rubric!$E$5:$E$46*Rubric!N$5:N$46)/(SUMPRODUCT((Rubric!$B$5:$B$46=$A10)*Rubric!$E$5:$E$46)*3),0) | K10: =IFERROR(SUMPRODUCT((Rubric!$B$5:$B$46=$A10)*Rubric!$E$5:$E$46*Rubric!O$5:O$46)/(SUMPRODUCT((Rubric!$B$5:$B$46=$A10)*Rubric!$E$5:$E$46)*3),0)
A11: Currency and content quality | B11: 0.07 | C11: =IFERROR(SUMPRODUCT((Rubric!$B$5:$B$46=$A11)*Rubric!$E$5:$E$46*Rubric!G$5:G$46)/(SUMPRODUCT((Rubric!$B$5:$B$46=$A11)*Rubric!$E$5:$E$46)*3),0) | D11: =IFERROR(SUMPRODUCT((Rubric!$B$5:$B$46=$A11)*Rubric!$E$5:$E$46*Rubric!H$5:H$46)/(SUMPRODUCT((Rubric!$B$5:$B$46=$A11)*Rubric!$E$5:$E$46)*3),0) | E11: =IFERROR(SUMPRODUCT((Rubric!$B$5:$B$46=$A11)*Rubric!$E$5:$E$46*Rubric!I$5:I$46)/(SUMPRODUCT((Rubric!$B$5:$B$46=$A11)*Rubric!$E$5:$E$46)*3),0) | F11: =IFERROR(SUMPRODUCT((Rubric!$B$5:$B$46=$A11)*Rubric!$E$5:$E$46*Rubric!J$5:J$46)/(SUMPRODUCT((Rubric!$B$5:$B$46=$A11)*Rubric!$E$5:$E$46)*3),0) | G11: =IFERROR(SUMPRODUCT((Rubric!$B$5:$B$46=$A11)*Rubric!$E$5:$E$46*Rubric!K$5:K$46)/(SUMPRODUCT((Rubric!$B$5:$B$46=$A11)*Rubric!$E$5:$E$46)*3),0) | H11: =IFERROR(SUMPRODUCT((Rubric!$B$5:$B$46=$A11)*Rubric!$E$5:$E$46*Rubric!L$5:L$46)/(SUMPRODUCT((Rubric!$B$5:$B$46=$A11)*Rubric!$E$5:$E$46)*3),0) | I11: =IFERROR(SUMPRODUCT((Rubric!$B$5:$B$46=$A11)*Rubric!$E$5:$E$46*Rubric!M$5:M$46)/(SUMPRODUCT((Rubric!$B$5:$B$46=$A11)*Rubric!$E$5:$E$46)*3),0) | J11: =IFERROR(SUMPRODUCT((Rubric!$B$5:$B$46=$A11)*Rubric!$E$5:$E$46*Rubric!N$5:N$46)/(SUMPRODUCT((Rubric!$B$5:$B$46=$A11)*Rubric!$E$5:$E$46)*3),0) | K11: =IFERROR(SUMPRODUCT((Rubric!$B$5:$B$46=$A11)*Rubric!$E$5:$E$46*Rubric!O$5:O$46)/(SUMPRODUCT((Rubric!$B$5:$B$46=$A11)*Rubric!$E$5:$E$46)*3),0)
A12: Enterprise readiness and trust | B12: 0.1 | C12: =IFERROR(SUMPRODUCT((Rubric!$B$5:$B$46=$A12)*Rubric!$E$5:$E$46*Rubric!G$5:G$46)/(SUMPRODUCT((Rubric!$B$5:$B$46=$A12)*Rubric!$E$5:$E$46)*3),0) | D12: =IFERROR(SUMPRODUCT((Rubric!$B$5:$B$46=$A12)*Rubric!$E$5:$E$46*Rubric!H$5:H$46)/(SUMPRODUCT((Rubric!$B$5:$B$46=$A12)*Rubric!$E$5:$E$46)*3),0) | E12: =IFERROR(SUMPRODUCT((Rubric!$B$5:$B$46=$A12)*Rubric!$E$5:$E$46*Rubric!I$5:I$46)/(SUMPRODUCT((Rubric!$B$5:$B$46=$A12)*Rubric!$E$5:$E$46)*3),0) | F12: =IFERROR(SUMPRODUCT((Rubric!$B$5:$B$46=$A12)*Rubric!$E$5:$E$46*Rubric!J$5:J$46)/(SUMPRODUCT((Rubric!$B$5:$B$46=$A12)*Rubric!$E$5:$E$46)*3),0) | G12: =IFERROR(SUMPRODUCT((Rubric!$B$5:$B$46=$A12)*Rubric!$E$5:$E$46*Rubric!K$5:K$46)/(SUMPRODUCT((Rubric!$B$5:$B$46=$A12)*Rubric!$E$5:$E$46)*3),0) | H12: =IFERROR(SUMPRODUCT((Rubric!$B$5:$B$46=$A12)*Rubric!$E$5:$E$46*Rubric!L$5:L$46)/(SUMPRODUCT((Rubric!$B$5:$B$46=$A12)*Rubric!$E$5:$E$46)*3),0) | I12: =IFERROR(SUMPRODUCT((Rubric!$B$5:$B$46=$A12)*Rubric!$E$5:$E$46*Rubric!M$5:M$46)/(SUMPRODUCT((Rubric!$B$5:$B$46=$A12)*Rubric!$E$5:$E$46)*3),0) | J12: =IFERROR(SUMPRODUCT((Rubric!$B$5:$B$46=$A12)*Rubric!$E$5:$E$46*Rubric!N$5:N$46)/(SUMPRODUCT((Rubric!$B$5:$B$46=$A12)*Rubric!$E$5:$E$46)*3),0) | K12: =IFERROR(SUMPRODUCT((Rubric!$B$5:$B$46=$A12)*Rubric!$E$5:$E$46*Rubric!O$5:O$46)/(SUMPRODUCT((Rubric!$B$5:$B$46=$A12)*Rubric!$E$5:$E$46)*3),0)
A13: Reach, scale and access | B13: 0.08 | C13: =IFERROR(SUMPRODUCT((Rubric!$B$5:$B$46=$A13)*Rubric!$E$5:$E$46*Rubric!G$5:G$46)/(SUMPRODUCT((Rubric!$B$5:$B$46=$A13)*Rubric!$E$5:$E$46)*3),0) | D13: =IFERROR(SUMPRODUCT((Rubric!$B$5:$B$46=$A13)*Rubric!$E$5:$E$46*Rubric!H$5:H$46)/(SUMPRODUCT((Rubric!$B$5:$B$46=$A13)*Rubric!$E$5:$E$46)*3),0) | E13: =IFERROR(SUMPRODUCT((Rubric!$B$5:$B$46=$A13)*Rubric!$E$5:$E$46*Rubric!I$5:I$46)/(SUMPRODUCT((Rubric!$B$5:$B$46=$A13)*Rubric!$E$5:$E$46)*3),0) | F13: =IFERROR(SUMPRODUCT((Rubric!$B$5:$B$46=$A13)*Rubric!$E$5:$E$46*Rubric!J$5:J$46)/(SUMPRODUCT((Rubric!$B$5:$B$46=$A13)*Rubric!$E$5:$E$46)*3),0) | G13: =IFERROR(SUMPRODUCT((Rubric!$B$5:$B$46=$A13)*Rubric!$E$5:$E$46*Rubric!K$5:K$46)/(SUMPRODUCT((Rubric!$B$5:$B$46=$A13)*Rubric!$E$5:$E$46)*3),0) | H13: =IFERROR(SUMPRODUCT((Rubric!$B$5:$B$46=$A13)*Rubric!$E$5:$E$46*Rubric!L$5:L$46)/(SUMPRODUCT((Rubric!$B$5:$B$46=$A13)*Rubric!$E$5:$E$46)*3),0) | I13: =IFERROR(SUMPRODUCT((Rubric!$B$5:$B$46=$A13)*Rubric!$E$5:$E$46*Rubric!M$5:M$46)/(SUMPRODUCT((Rubric!$B$5:$B$46=$A13)*Rubric!$E$5:$E$46)*3),0) | J13: =IFERROR(SUMPRODUCT((Rubric!$B$5:$B$46=$A13)*Rubric!$E$5:$E$46*Rubric!N$5:N$46)/(SUMPRODUCT((Rubric!$B$5:$B$46=$A13)*Rubric!$E$5:$E$46)*3),0) | K13: =IFERROR(SUMPRODUCT((Rubric!$B$5:$B$46=$A13)*Rubric!$E$5:$E$46*Rubric!O$5:O$46)/(SUMPRODUCT((Rubric!$B$5:$B$46=$A13)*Rubric!$E$5:$E$46)*3),0)
A14: Commercial transparency and value | B14: 0.07 | C14: =IFERROR(SUMPRODUCT((Rubric!$B$5:$B$46=$A14)*Rubric!$E$5:$E$46*Rubric!G$5:G$46)/(SUMPRODUCT((Rubric!$B$5:$B$46=$A14)*Rubric!$E$5:$E$46)*3),0) | D14: =IFERROR(SUMPRODUCT((Rubric!$B$5:$B$46=$A14)*Rubric!$E$5:$E$46*Rubric!H$5:H$46)/(SUMPRODUCT((Rubric!$B$5:$B$46=$A14)*Rubric!$E$5:$E$46)*3),0) | E14: =IFERROR(SUMPRODUCT((Rubric!$B$5:$B$46=$A14)*Rubric!$E$5:$E$46*Rubric!I$5:I$46)/(SUMPRODUCT((Rubric!$B$5:$B$46=$A14)*Rubric!$E$5:$E$46)*3),0) | F14: =IFERROR(SUMPRODUCT((Rubric!$B$5:$B$46=$A14)*Rubric!$E$5:$E$46*Rubric!J$5:J$46)/(SUMPRODUCT((Rubric!$B$5:$B$46=$A14)*Rubric!$E$5:$E$46)*3),0) | G14: =IFERROR(SUMPRODUCT((Rubric!$B$5:$B$46=$A14)*Rubric!$E$5:$E$46*Rubric!K$5:K$46)/(SUMPRODUCT((Rubric!$B$5:$B$46=$A14)*Rubric!$E$5:$E$46)*3),0) | H14: =IFERROR(SUMPRODUCT((Rubric!$B$5:$B$46=$A14)*Rubric!$E$5:$E$46*Rubric!L$5:L$46)/(SUMPRODUCT((Rubric!$B$5:$B$46=$A14)*Rubric!$E$5:$E$46)*3),0) | I14: =IFERROR(SUMPRODUCT((Rubric!$B$5:$B$46=$A14)*Rubric!$E$5:$E$46*Rubric!M$5:M$46)/(SUMPRODUCT((Rubric!$B$5:$B$46=$A14)*Rubric!$E$5:$E$46)*3),0) | J14: =IFERROR(SUMPRODUCT((Rubric!$B$5:$B$46=$A14)*Rubric!$E$5:$E$46*Rubric!N$5:N$46)/(SUMPRODUCT((Rubric!$B$5:$B$46=$A14)*Rubric!$E$5:$E$46)*3),0) | K14: =IFERROR(SUMPRODUCT((Rubric!$B$5:$B$46=$A14)*Rubric!$E$5:$E$46*Rubric!O$5:O$46)/(SUMPRODUCT((Rubric!$B$5:$B$46=$A14)*Rubric!$E$5:$E$46)*3),0)
A15: Weight total | B15: =SUM(B5:B14)
A16: Weight check | B16: =IF(ROUND(B15,4)=1,"OK","Adjust weights")
A18: OVERALL WEIGHTED SCORE | C18: =SUMPRODUCT($B$5:$B$14,C5:C14)/SUM($B$5:$B$14) | D18: =SUMPRODUCT($B$5:$B$14,D5:D14)/SUM($B$5:$B$14) | E18: =SUMPRODUCT($B$5:$B$14,E5:E14)/SUM($B$5:$B$14) | F18: =SUMPRODUCT($B$5:$B$14,F5:F14)/SUM($B$5:$B$14) | G18: =SUMPRODUCT($B$5:$B$14,G5:G14)/SUM($B$5:$B$14) | H18: =SUMPRODUCT($B$5:$B$14,H5:H14)/SUM($B$5:$B$14) | I18: =SUMPRODUCT($B$5:$B$14,I5:I14)/SUM($B$5:$B$14) | J18: =SUMPRODUCT($B$5:$B$14,J5:J14)/SUM($B$5:$B$14) | K18: =SUMPRODUCT($B$5:$B$14,K5:K14)/SUM($B$5:$B$14)
A19: Rank (competitors only) | C19: =RANK(C18,$C$18:$J$18) | D19: =RANK(D18,$C$18:$J$18) | E19: =RANK(E18,$C$18:$J$18) | F19: =RANK(F18,$C$18:$J$18) | G19: =RANK(G18,$C$18:$J$18) | H19: =RANK(H18,$C$18:$J$18) | I19: =RANK(I18,$C$18:$J$18) | J19: =RANK(J18,$C$18:$J$18) | K19: n/a — design target
A20: Gate failures | C20: =COUNTIFS(Rubric!$F$5:$F$46,"Y",Rubric!G$5:G$46,"<2") | D20: =COUNTIFS(Rubric!$F$5:$F$46,"Y",Rubric!H$5:H$46,"<2") | E20: =COUNTIFS(Rubric!$F$5:$F$46,"Y",Rubric!I$5:I$46,"<2") | F20: =COUNTIFS(Rubric!$F$5:$F$46,"Y",Rubric!J$5:J$46,"<2") | G20: =COUNTIFS(Rubric!$F$5:$F$46,"Y",Rubric!K$5:K$46,"<2") | H20: =COUNTIFS(Rubric!$F$5:$F$46,"Y",Rubric!L$5:L$46,"<2") | I20: =COUNTIFS(Rubric!$F$5:$F$46,"Y",Rubric!M$5:M$46,"<2") | J20: =COUNTIFS(Rubric!$F$5:$F$46,"Y",Rubric!N$5:N$46,"<2") | K20: =COUNTIFS(Rubric!$F$5:$F$46,"Y",Rubric!O$5:O$46,"<2")
A21: Criteria scored | C21: =COUNT(Rubric!G$5:G$46)&" of 42" | D21: =COUNT(Rubric!H$5:H$46)&" of 42" | E21: =COUNT(Rubric!I$5:I$46)&" of 42" | F21: =COUNT(Rubric!J$5:J$46)&" of 42" | G21: =COUNT(Rubric!K$5:K$46)&" of 42" | H21: =COUNT(Rubric!L$5:L$46)&" of 42" | I21: =COUNT(Rubric!M$5:M$46)&" of 42" | J21: =COUNT(Rubric!N$5:N$46)&" of 42" | K21: =COUNT(Rubric!O$5:O$46)&" of 42"
A23: Gate criteria: D1.1, D3.1, D3.2, D3.3, D5.1. A gate scored below 2 is a gate failure whatever the total.
A24: The design-target column is all 3s by construction (100%). It shows the bar the product is designed to, not a measured score.

Sheet Rubric
A1: Rubric — MSL AI Skills training platform vs competitors
A2: Yellow cells are editable. Scores 0–3 from public evidence checked Oct 2026. Last column is a DESIGN TARGET, not an evidence score.
A4: ID | B4: Domain | C4: Criterion | D4: What a 3 looks like | E4: Weight (1–3) | F4: Gate | G4: MSL Society | H4: ACMA | I4: MAPS | J4: CELforPharma | K4: Eularis | L4: MA Value / MSL Mastery | M4: Inizio MSL Interact | N4: Section (horizontal) | O4: MSL AI Skills (design target)
A5: D1.1 | B5: MSL role specificity | C5: Anchored to real MSL day-to-day tasks | D5: Curriculum built around named MSL tasks: literature triage, pre-call planning, KOL/KEE profiling, insight synthesis, congress summaries | E5: 3 | F5: Y | G5: 2 | H5: 2 | I5: 1 | J5: 2 | K5: 1 | L5: 2 | M5: 1 | N5: 0 | O5: 3
A6: D1.2 | B6: MSL role specificity | C6: Mapped to an MSL competency framework or job description | D6: Published mapping of modules to a field-medical competency framework and a representative MSL JD | E6: 2 | G6: 1 | H6: 2 | I6: 1 | J6: 0 | K6: 0 | L6: 0 | M6: 0 | N6: 0 | O6: 3
A7: D1.3 | B7: MSL role specificity | C7: Worked examples across therapeutic areas | D7: Examples in 3+ TAs or a configurable TA case layer | E7: 2 | G7: 0 | H7: 0 | I7: 0 | J7: 0 | K7: 0 | L7: 1 | M7: 2 | N7: 0 | O7: 3
A8: D1.4 | B8: MSL role specificity | C8: Pathways by seniority | D8: Distinct documented tracks for new MSL, senior MSL, manager/L&D lead | E8: 2 | G8: 1 | H8: 1 | I8: 1 | J8: 0 | K8: 1 | L8: 1 | M8: 1 | N8: 2 | O8: 3
A9: D2.1 | B9: Hands-on depth across the AI stack | C9: Hands-on applied prompt engineering | D9: Practice exercises on real scientific/medical tasks | E9: 3 | G9: 2 | H9: 2 | I9: 0 | J9: 2 | K9: 1 | L9: 2 | M9: 0 | N9: 2 | O9: 3
A10: D2.2 | B10: Hands-on depth across the AI stack | C10: AI workflows and tool chaining | D10: Chaining email, calendar, notes, reference manager, read-only CRM with exercises | E10: 2 | G10: 1 | H10: 1 | I10: 0 | J10: 1 | K10: 1 | L10: 2 | M10: 0 | N10: 2 | O10: 3
A11: D2.3 | B11: Hands-on depth across the AI stack | C11: Vibe coding / low-code personal apps | D11: Learners build a working personal tool | E11: 2 | G11: 0 | H11: 0 | I11: 0 | J11: 2 | K11: 0 | L11: 0 | M11: 0 | N11: 1 | O11: 3
A12: D2.4 | B12: Hands-on depth across the AI stack | C12: Custom assistants and agents with guardrails | D12: Learners build, test and evaluate an assistant/agent | E12: 3 | G12: 1 | H12: 2 | I12: 0 | J12: 1 | K12: 0 | L12: 2 | M12: 0 | N12: 2 | O12: 3
A13: D2.5 | B13: Hands-on depth across the AI stack | C13: Automation with human review gates | D13: Automation of recurring tasks taught with explicit review gates | E13: 2 | G13: 0 | H13: 1 | I13: 0 | J13: 1 | K13: 0 | L13: 1 | M13: 0 | N13: 1 | O13: 3
A14: D2.6 | B14: Hands-on depth across the AI stack | C14: Learn-by-shipping artifact per module | D14: Every module produces a usable work artifact | E14: 2 | G14: 1 | H14: 1 | I14: 0 | J14: 1 | K14: 1 | L14: 1 | M14: 0 | N14: 1 | O14: 3
A15: D3.1 | B15: Compliance embedded | C15: Non-promotional, off-label and PhRMA Code guardrails in AI use | D15: Explicit module/content on scientific exchange rules when using AI | E15: 3 | F15: Y | G15: 1 | H15: 2 | I15: 1 | J15: 1 | K15: 0 | L15: 1 | M15: 1 | N15: 0 | O15: 3
A16: D3.2 | B16: Compliance embedded | C16: Data governance: PHI, confidential, embargoed data; sanctioned tools | D16: Explicit content on what may never enter public models; HIPAA; enterprise instances | E16: 3 | F16: Y | G16: 0 | H16: 2 | I16: 1 | J16: 1 | K16: 1 | L16: 0 | M16: 0 | N16: 1 | O16: 3
A17: D3.3 | B17: Compliance embedded | C17: Pharmacovigilance: AEs surfaced by AI routed to humans | D17: Explicit content and exercise on AE/PQC routing | E17: 3 | F17: Y | G17: 0 | H17: 1 | I17: 1 | J17: 0 | K17: 0 | L17: 0 | M17: 0 | N17: 0 | O17: 3
A18: D3.4 | B18: Compliance embedded | C18: AI output as draft needing MLR / scientific review | D18: Explicit content positioning all output as drafts | E18: 2 | G18: 2 | H18: 2 | I18: 1 | J18: 1 | K18: 1 | L18: 1 | M18: 1 | N18: 0 | O18: 3
A19: D3.5 | B19: Compliance embedded | C19: Prototype vs IT-governed production | D19: Explicit content on pharma IT/security boundaries | E19: 2 | G19: 0 | H19: 0 | I19: 0 | J19: 0 | K19: 1 | L19: 0 | M19: 0 | N19: 0 | O19: 3
A20: D4.1 | B20: Learning design for a field schedule | C20: Microlearning units | D20: Documented units of about 15 minutes or less | E20: 2 | G20: 0 | H20: 1 | I20: 1 | J20: 0 | K20: 1 | L20: 1 | M20: 0 | N20: 1 | O20: 3
A21: D4.2 | B21: Learning design for a field schedule | C21: Mobile / asynchronous access | D21: On-demand and usable on a phone | E21: 2 | G21: 0 | H21: 2 | I21: 3 | J21: 0 | K21: 2 | L21: 2 | M21: 2 | N21: 2 | O21: 3
A22: D4.3 | B22: Learning design for a field schedule | C22: Reinforcement and reusable asset library | D22: Spaced review, prompt cards, searchable prompt/agent library | E22: 1 | G22: 0 | H22: 1 | I22: 1 | J22: 1 | K22: 2 | L22: 2 | M22: 0 | N22: 3 | O22: 3
A23: D4.4 | B23: Learning design for a field schedule | C23: Live cohorts / office hours in US time zones | D23: Recurring live sessions in US hours | E23: 1 | G23: 2 | H23: 0 | I23: 2 | J23: 0 | K23: 1 | L23: 1 | M23: 0 | N23: 3 | O23: 3
A24: D5.1 | B24: Assessment and credential | C24: Performance-based assessment of AI competence | D24: Graded practical assessment, not attendance | E24: 3 | F24: Y | G24: 0 | H24: 2 | I24: 1 | J24: 0 | K24: 0 | L24: 0 | M24: 1 | N24: 2 | O24: 3
A25: D5.2 | B25: Assessment and credential | C25: Recognized certification / credential | D25: Named credential with industry recognition | E25: 3 | G25: 1 | H25: 3 | I25: 1 | J25: 1 | K25: 0 | L25: 0 | M25: 0 | N25: 2 | O25: 3
A26: D5.3 | B26: Assessment and credential | C26: CE/CME or accredited PD credit | D26: Accredited credit stated | E26: 1 | G26: 1 | H26: 2 | I26: 1 | J26: 0 | K26: 0 | L26: 0 | M26: 0 | N26: 0 | O26: 3
A27: D5.4 | B27: Assessment and credential | C27: Capstone that measurably saves time | D27: Documented capstone with time-saved measure | E27: 2 | G27: 0 | H27: 0 | I27: 0 | J27: 1 | K27: 0 | L27: 0 | M27: 0 | N27: 1 | O27: 3
A28: D6.1 | B28: Outcomes and measurement | C28: Pre/post efficiency or skill metrics | D28: Documented measurement plan | E28: 2 | G28: 0 | H28: 1 | I28: 1 | J28: 0 | K28: 0 | L28: 1 | M28: 1 | N28: 2 | O28: 3
A29: D6.2 | B29: Outcomes and measurement | C29: Published quantified learner outcomes | D29: Quantified outcomes or case studies public | E29: 2 | G29: 0 | H29: 1 | I29: 0 | J29: 1 | K29: 1 | L29: 1 | M29: 0 | N29: 3 | O29: 3
A30: D6.3 | B30: Outcomes and measurement | C30: Manager / enterprise reporting | D30: Dashboard or reports for buyers | E30: 2 | G30: 0 | H30: 0 | I30: 0 | J30: 0 | K30: 2 | L30: 1 | M30: 3 | N30: 3 | O30: 3
A31: D7.1 | B31: Currency and content quality | C31: Documented content refresh cadence | D31: Stated cadence for AI tool changes | E31: 2 | G31: 0 | H31: 1 | I31: 1 | J31: 0 | K31: 1 | L31: 0 | M31: 1 | N31: 1 | O31: 3
A32: D7.2 | B32: Currency and content quality | C32: Faculty with medical-affairs and AI expertise | D32: Named faculty with both | E32: 2 | G32: 1 | H32: 1 | I32: 2 | J32: 2 | K32: 1 | L32: 2 | M32: 0 | N32: 0 | O32: 3
A33: D7.3 | B33: Currency and content quality | C33: Tool-agnostic across enterprise AI stacks | D33: Covers ChatGPT Enterprise, Copilot, Claude, Gemini | E33: 2 | G33: 1 | H33: 3 | I33: 0 | J33: 3 | K33: 0 | L33: 2 | M33: 0 | N33: 3 | O33: 3
A34: D8.1 | B34: Enterprise readiness and trust | C34: Team / enterprise licensing or private cohorts | D34: Documented team offer | E34: 2 | G34: 2 | H34: 2 | I34: 3 | J34: 3 | K34: 3 | L34: 3 | M34: 2 | N34: 3 | O34: 3
A35: D8.2 | B35: Enterprise readiness and trust | C35: Security and privacy posture | D35: SOC 2/ISO certification or a trust page | E35: 2 | G35: 0 | H35: 1 | I35: 2 | J35: 1 | K35: 1 | L35: 1 | M35: 0 | N35: 1 | O35: 3
A36: D8.3 | B36: Enterprise readiness and trust | C36: LMS / SSO integration | D36: Documented LMS/SSO support | E36: 1 | G36: 0 | H36: 1 | I36: 1 | J36: 0 | K36: 0 | L36: 0 | M36: 1 | N36: 3 | O36: 3
... A46: D10.4 | B46: Commercial transparency and value | C46: Free sample or trial | D46: Sample content available | E46: 1 | G46: 1 | H46: 1 | I46: 2 | J46: 1 | K46: 2 | L46: 2 | M46: 0 | N46: 3 | O46: 3

Sheet Evidence
A1: Evidence — paraphrased note behind each score
A2: ID and criterion pull from Rubric. Sources sheet lists every URL.
A4: ID | B4: Criterion | C4: MSL Society — evidence | D4: ACMA — evidence | E4: MAPS — evidence | F4: CELforPharma — evidence | G4: Eularis — evidence | H4: MA Value / MSL Mastery — evidence | I4: Inizio MSL Interact — evidence | J4: Section (horizontal) — evidence | K4: MSL AI Skills (design target) — evidence
A5: =Rubric!A5 | B5: =Rubric!C5 | C5: Use cases named: KOL prep, AI-supported SLR, literature summarization, insight synthesis; within one 4-hour session | D5: Applied use for KOL profiling, literature review, physician inquiries; MSL insights module; not fully task-built | E5: Webinars discuss AI in MSL workflows; no curriculum built on MSL tasks | F5: Day 1 covers MA use cases: literature review, congress prep, competitor intel; Day 2 MSL insight analysis workshop | G5: function tracks include medical affairs; no named MSL tasks found | H5: Covers KOL profiling, pre-meeting planning, literature, email and congress; no published task curriculum | I5: Rehearses HCP conversations only; no literature triage, KOL profiling, insight or congress tasks | J5: Courses by business function only; no MSL tasks | K5: DESIGN TARGET — not evidence; specified in founder's meta-prompt (Aug 2026)
A6: =Rubric!A6 | B6: =Rubric!C6 | C6: Ends with competency reflection; MSL-BC rests on 2017 job task analysis but no AI mapping | D6: Built on ACMA's own 13-competency framework; no published AI-to-JD mapping | E6: Org-wide 42-competency framework; no AI course mapping published | F6: no evidence found of mapping to an MSL competency framework | G6: no evidence found of competency framework mapping | H6: No evidence found of competency-framework mapping | I6: No evidence found of mapping to an MSL competency framework | J6: No evidence found of mapping to an MSL framework | K6: DESIGN TARGET — not evidence; specified in founder's meta-prompt (Aug 2026)
A7: =Rubric!A7 | B7: =Rubric!C7 | C7: No evidence found of therapeutic-area examples or electives | D7: No evidence found of multi-TA examples or TA electives | E7: No evidence found of TA-specific AI examples | F7: no evidence found of multi-TA examples or TA electives | G7: no evidence found of multi-TA examples | H7: Testimonials span several TAs; no TA-specific AI examples | I7: Avatars specific to a therapeutic area and configurable; no named TAs or worked examples | J7: No therapeutic-area or healthcare examples in catalog | K7: DESIGN TARGET — not evidence; specified in founder's meta-prompt (Aug 2026)
A8: =Rubric!A8 | B8: =Rubric!C8 | C8: One track only; no new/senior/manager AI pathways | D8: Single certification for all levels | E8: AI Foundations then advanced course; no role tracks | F8: one course for all levels; no seniority tracks found | G8: executive fluency and operational tracks; not MSL seniority tracks | H8: New-MSL and leader programs exist but not AI-specific tracks | I8: Says it supports onboarding through advanced skill development; no documented tracks | J8: Beginner to advanced courses plus team-leader and Head of AI tracks | K8: DESIGN TARGET — not evidence; specified in founder's meta-prompt (Aug 2026)
A9: =Rubric!A9 | B9: =Rubric!C9 | C9: Outcomes include applying prompt strategies for accuracy and compliance; hands-on exercises not stated | D9: Prompt engineering for medical affairs listed; simulation cases mentioned; exercise detail unclear | E9: No evidence found of hands-on prompt exercises | F9: hands-on prompting and literature classification exercises on Day 1 | G9: AI-cademy cheatsheets on LLM prompts; no exercises found | H9: Hands-on Copilot prompt writing; participants leave with reusable prompts | I9: No evidence found; rehearsal tool, does not teach prompting | J9: Prompt course and AI-scored prompting simulations; generic, not medical | K9: DESIGN TARGET — not evidence; specified in founder's meta-prompt (Aug 2026)
A10: =Rubric!A10 | B10: =Rubric!C10 | C10: Names ChatGPT and Elicit only; no chaining with email, calendar, CRM | D10: Names ChatGPT, Claude, Gemini, Perplexity; no workflow chaining | E10: No evidence found | F10: agentic AI planning session; no email/calendar/CRM chaining exercises found | G10: operational AI workflows mentioned; no tool-chaining exercises | H10: Email organizing, Outlook integration and scheduled prompts; exercise depth unclear | I10: No evidence found of teaching AI workflows or tool chaining | J10: Courses on custom GPT with Zapier and team workflows | K10: DESIGN TARGET — not evidence; specified in founder's meta-prompt (Aug 2026)
A11: =Rubric!A11 | B11: =Rubric!C11 | C11: No evidence found of no-code or vibe-coding app building | D11: No evidence found of vibe coding or app building | E11: No evidence found | F11: AI-assisted coding workshop in Google Colab for MSL insight analysis | G11: no evidence found of no-code or vibe-coding builds | H11: No evidence found of vibe coding or app building | I11: No evidence found of no-code or vibe-coding building | J11: No vibe-coding course; no-code agents in Copilot Studio only | K11: DESIGN TARGET — not evidence; specified in founder's meta-prompt (Aug 2026)
A12: =Rubric!A12 | B12: =Rubric!C12 | C12: AI agents explained; MSLs learn to work with technical teams rather than build | D12: Press release says learners build no-code AI agents; guardrails/evaluation not described | E12: No evidence found of building GPTs or agents | F12: conversational AI for HCP education and agent planning; no build-and-test of own assistant | G12: no evidence found of building custom assistants or agents | H12: Learners build an agent in Copilot or ChatGPT; no guardrails or evaluation taught | I12: No evidence found of learners building assistants or agents | J12: Learners build custom GPTs and Claude/ChatGPT/Copilot agents; guardrails and evaluation not evidenced | K12: DESIGN TARGET — not evidence; specified in founder's meta-prompt (Aug 2026)
A13: =Rubric!A13 | B13: =Rubric!C13 | C13: No evidence found of automation with human review gates | D13: Agent automation of repetitive tasks mentioned; no review gates | E13: No evidence found | F13: agentic planning mentioned; no automation exercises with human review gates | G13: no evidence found of automation with review gates | H13: Scheduled prompts taught; human review only in a blog example | I13: No evidence found of teaching automation | J13: Zapier automation taught; no explicit human review gates | K13: DESIGN TARGET — not evidence; specified in founder's meta-prompt (Aug 2026)
A14: =Rubric!A14 | B14: =Rubric!C14 | C14: Only output is a personal AI learning and action plan | D14: Productivity tools listed; no per-module artifact | E14: No evidence found | F14: project prioritisation and development workshops; artifact per module not documented | G14: learners leave with a personal AI plan; no per-module artifacts | H14: Workshop yields one agent and prompts; no per-module artifacts | I14: No evidence found of learners producing work artifacts | J14: Learners save AI use cases; no artifact per module | K14: DESIGN TARGET — not evidence; specified in founder's meta-prompt (Aug 2026)
A15: =Rubric!A15 | B15: =Rubric!C15 | C15: Generic AI compliance-risk and ethics module; no explicit off-label or PhRMA Code content | D15: Compliance and data privacy module, FDA and industry standards; PhRMA attestation sold separately | E15: Podcast touches codes of practice and FDA guidance; no off-label AI module | F15: responsible AI covers disclosure; no explicit off-label/promotional/PhRMA content found | G15: no evidence found of promotional/off-label/PhRMA content | H15: Compliance mentioned only in a testimonial; no promotional/off-label module | I15: Aims at compliant HCP engagement; no content on off-label or PhRMA Code | J15: No pharma promotional-compliance content | K15: DESIGN TARGET — not evidence; specified in founder's meta-prompt (Aug 2026)
A16: =Rubric!A16 | B16: =Rubric!C16 | C16: No evidence found of PHI, confidential data, enterprise-tool or HIPAA content | D16: Covers data privacy risks and compliant AI workflows; HIPAA/PHI specifics not stated | E16: Podcast on GDPR and proprietary data leakage to LLMs; not a module | F16: privacy and prompt injection listed; no HIPAA or enterprise-tool guidance | G16: foundations cover governance and data readiness; no PHI/HIPAA specifics | H16: No evidence found of data governance, PHI or HIPAA content | I16: No evidence found on PHI or data-governance content | J16: Generic Responsible AI Use module; no PHI or HIPAA content | K16: DESIGN TARGET — not evidence; specified in founder's meta-prompt (Aug 2026)
... A46: =Rubric!A46 | B46: =Rubric!C46 | C46: Free guest membership and reports; no AI preview | D46: Free course is telehealth, not AI | E46: Free primer and free AI podcast | F46: free webinars and articles; no course preview | G46: free AI tools guide (business email required) and free webinars | H46: Free AI blog guides and prompt downloads | I46: No free trial or public demo found | J46: Free Basic tier with lesson videos and certificates | K46: DESIGN TARGET — not evidence; specified in founder's meta-prompt (Aug 2026)

Sheet Gap analysis
A1: Gap analysis — where the white space is
A2: Best competitor excludes the design target. Category: Differentiator if best ≤ 1, Improve on best if best = 2, Parity if best = 3.
A4: ID | B4: Criterion | C4: Gate | D4: Criterion weight | E4: Best competitor score | F4: Leaders (as scored) | G4: Gap to 3 | H4: Category | I4: MSL AI Skills score | J4: MSL AI Skills vs best | K4: MSL AI Skills position
A5: =Rubric!A5 | B5: =Rubric!C5 | C5: =Rubric!F5 | D5: =Rubric!E5 | E5: =MAX(Rubric!G5:N5) | F5: MSL Society, ACMA, CELforPharma, MA Value / MSL Mastery | G5: =3-E5 | H5: =IF(E5<=1,"Differentiator",IF(E5=2,"Improve on best","Parity")) | I5: =Rubric!O5 | J5: =I5-E5 | K5: =IF(J5>0,"leads",IF(J5=0,"Level","Behind"))
A6: =Rubric!A6 | B6: =Rubric!C6 | C6: =Rubric!F6 | D6: =Rubric!E6 | E6: =MAX(Rubric!G6:N6) | F6: ACMA | G6: =3-E6 | H6: =IF(E6<=1,"Differentiator",IF(E6=2,"Improve on best","Parity")) | I6: =Rubric!O6 | J6: =I6-E6 | K6: =IF(J6>0,"leads",IF(J6=0,"Level","Behind"))
A7: =Rubric!A7 | B7: =Rubric!C7 | C7: =Rubric!F7 | D7: =Rubric!E7 | E7: =MAX(Rubric!G7:N7) | F7: Inizio MSL Interact | G7: =3-E7 | H7: =IF(E7<=1,"Differentiator",IF(E7=2,"Improve on best","Parity")) | I7: =Rubric!O7 | J7: =I7-E7 | K7: =IF(J7>0,"leads",IF(J7=0,"Level","Behind"))
A8: =Rubric!A8 | B8: =Rubric!C8 | C8: =Rubric!F8 | D8: =Rubric!E8 | E8: =MAX(Rubric!G8:N8) | F8: Section (horizontal) | G8: =3-E8 | H8: =IF(E8<=1,"Differentiator",IF(E8=2,"Improve on best","Parity")) | I8: =Rubric!O8 | J8: =I8-E8 | K8: =IF(J8>0,"leads",IF(J8=0,"Level","Behind"))
A9: =Rubric!A9 | B9: =Rubric!C9 | C9: =Rubric!F9 | D9: =Rubric!E9 | E9: =MAX(Rubric!G9:N9) | F9: MSL Society, ACMA, CELforPharma, MA Value / MSL Mastery, Section (horizontal) | G9: =3-E9 | H9: =IF(E9<=1,"Differentiator",IF(E9=2,"Improve on best","Parity")) | I9: =Rubric!O9 | J9: =I9-E9 | K9: =IF(J9>0,"leads",IF(J9=0,"Level","Behind"))
A10: =Rubric!A10 | B10: =Rubric!C10 | C10: =Rubric!F10 | D10: =Rubric!E10 | E10: =MAX(Rubric!G10:N10) | F10: MA Value / MSL Mastery, Section (horizontal) | G10: =3-E10 | H10: =IF(E10<=1,"Differentiator",IF(E10=2,"Improve on best","Parity")) | I10: =Rubric!O10 | J10: =I10-E10 | K10: =IF(J10>0,"leads",IF(J10=0,"Level","Behind"))
A11: =Rubric!A11 | B11: =Rubric!C11 | C11: =Rubric!F11 | D11: =Rubric!E11 | E11: =MAX(Rubric!G11:N11) | F11: CELforPharma | G11: =3-E11 | H11: =IF(E11<=1,"Differentiator",IF(E11=2,"Improve on best","Parity")) | I11: =Rubric!O11 | J11: =I11-E11 | K11: =IF(J11>0,"leads",IF(J11=0,"Level","Behind"))
A12: =Rubric!A12 | B12: =Rubric!C12 | C12: =Rubric!F12 | D12: =Rubric!E12 | E12: =MAX(Rubric!G12:N12) | F12: ACMA, MA Value / MSL Mastery, Section (horizontal) | G12: =3-E12 | H12: =IF(E12<=1,"Differentiator",IF(E12=2,"Improve on best","Parity")) | I12: =Rubric!O12 | J12: =I12-E12 | K12: =IF(J12>0,"leads",IF(J12=0,"Level","Behind"))
A13: =Rubric!A13 | B13: =Rubric!C13 | C13: =Rubric!F13 | D13: =Rubric!E13 | E13: =MAX(Rubric!G13:N13) | F13: ACMA, CELforPharma, MA Value / MSL Mastery, Section (horizontal) | G13: =3-E13 | H13: =IF(E13<=1,"Differentiator",IF(E13=2,"Improve on best","Parity")) | I13: =Rubric!O13 | J13: =I13-E13 | K13: =IF(J13>0,"leads",IF(J13=0,"Level","Behind"))
A14: =Rubric!A14 | B14: =Rubric!C14 | C14: =Rubric!F14 | D14: =Rubric!E14 | E14: =MAX(Rubric!G14:N14) | F14: MSL Society, ACMA, CELforPharma, Eularis, MA Value / MSL Mastery, Section (horizontal) | G14: =3-E14 | H14: =IF(E14<=1,"Differentiator",IF(E14=2,"Improve on best","Parity")) | I14: =Rubric!O14 | J14: =I14-E14 | K14: =IF(J14>0,"leads",IF(J14=0,"Level","Behind"))
A15: =Rubric!A15 | B15: =Rubric!C15 | C15: =Rubric!F15 | D15: =Rubric!E15 | E15: =MAX(Rubric!G15:N15) | F15: ACMA | G15: =3-E15 | H15: =IF(E15<=1,"Differentiator",IF(E15=2,"Improve on best","Parity")) | I15: =Rubric!O15 | J15: =I15-E15 | K15: =IF(J15>0,"leads",IF(J15=0,"Level","Behind"))
A16: =Rubric!A16 | B16: =Rubric!C16 | C16: =Rubric!F16 | D16: =Rubric!E16 | E16: =MAX(Rubric!G16:N16) | F16: ACMA | G16: =3-E16 | H16: =IF(E16<=1,"Differentiator",IF(E16=2,"Improve on best","Parity")) | I16: =Rubric!O16 | J16: =I16-E16 | K16: =IF(J16>0,"leads",IF(J16=0,"Level","Behind"))
... A46: =Rubric!A46 | B46: =Rubric!C46 | C46: =Rubric!F46 | D46: =Rubric!E46 | E46: =MAX(Rubric!G46:N46) | F46: Section (horizontal) | G46: =3-E46 | H46: =IF(E46<=1,"Differentiator",IF(E46=2,"Improve on best","Parity")) | I46: =Rubric!O46 | J46: =I46-E46 | K46: =IF(J46>0,"leads",IF(J46=0,"Level","Behind"))
A48: Differentiator | B48: =COUNTIF($H$5:$H$46,A48) | D48: leads | E48: =COUNTIF($K$5:$K$46,D48)
A49: Improve on best | B49: =COUNTIF($H$5:$H$46,A49) | D49: Level | E49: =COUNTIF($K$5:$K$46,D49)
A50: Parity | B50: =COUNTIF($H$5:$H$46,A50) | D50: Behind | E50: =COUNTIF($K$5:$K$46,D50)
A53: ID | B53: Roadmap note — what MSL AI Skills needs to earn this score
A54: D1.1 | B54: Core of the concept; build every module on a named MSL task
A55: D1.2 | B55: Publish the competency/JD map; needs licensed framework or own framework
A56: D1.3 | B56: Rotate examples across oncology, immunology, rare, cardiometabolic, vaccines, CNS
A57: D1.4 | B57: Foundations / Accelerator / Builder tracks
A58: D2.1 | B58: Build first; prompt cards and graded exercises
A59: D2.2 | B59: Needs sandbox accounts that mirror enterprise tools
A60: D2.3 | B60: Sandboxed builds; clear prototype-vs-production line
A61: D2.4 | B61: Agent module with evaluation checklist and human checkpoints
A62: D2.5 | B62: Meeting-summary and congress-digest automations with review step
A63: D2.6 | B63: 10–20 minute build at the end of every module
A64: D3.1 | B64: Needs medical-affairs compliance reviewer sign-off
... A95: D10.4 | B95: Free first module

Sheet Sources
A1: Sources — every page behind a score
A2: Checked October 2026.
A4: Tool | B4: Source URL
A5: MSL Society | B5: https://members.themsls.org/events/EventDetails.aspx?id=2071997
A6: MSL Society | B6: https://themsls.org/msl-board-certification/
A7: MSL Society | B7: https://themsls.org/staying-relevant-and-effective-as-an-msl-in-the-era-of-ai/
A8: MSL Society | B8: https://themsls.org/iacet-accreditation/
A9: MSL Society | B9: https://members.themsls.org/event/AIandHEORTrainingBundle
A10: MSL Society | B10: https://themsls.org/customized-medical-science-liaison-training/
A11: MSL Society | B11: https://members.themsls.org/page/joinnow
A12: MSL Society | B12: https://www.themsls.org/
A13: MSL Society | B13: https://themsls.org/project/2026-medical-affairs-perspectives-on-ai-for-actionable-insight-collection-and-analysis/
A14: ACMA | B14: https://aijourn.com/?p=438353
A15: ACMA | B15: https://www.medicalaffairsspecialist.org/bcmas
... A69: Market evidence | B69: https://www.sectionai.com/pricing

Sheet Players
A1: Players
A2: Profiles from this session's research (Oct 2026).
A4: Player | B4: Segment | C4: Profile | D4: Source
A5: MSL Society | B5: MSL association (audience incumbent) | C5: US 501(c)(3); CEO-led. 4-hour live Zoom 'Staying Relevant and Effective as an MSL in the Era of AI', $500 non-member / $450 member; last run 14 Aug 2026, next date TBD. No assessment, certificate, CEU or recording for the AI course. Owns MSL membership, journal, conference and MSL-BC certification (which does not cover AI). Team training clients named org-wide. | D5: https://themsls.org/staying-relevant-and-effective-as-an-msl-in-the-era-of-ai/
A6: ACMA | B6: Medical-affairs certification body | C6: Privately held (Oradell, NJ). BCMAS board certification $2,399 (~30 h, self-paced, 13 modules) added AI content Nov 2025 incl. no-code agents per press release. Knowledge exam, no practical AI assessment. CME via ScientiaCME on four non-AI modules. Named team clients Gilead, Sanofi, Novartis, Baxter. Closest to the certification moat. | D6: https://www.medicalaffairsspecialist.org/bcmas
A7: MAPS | B7: Medical-affairs society | C7: Colorado non-profit, 18,000+ members in 400+ companies. AI Foundations eLearning (80% quiz certificate) and ~120-min advanced AI course; heavy 2026 AI webinar and white-paper output. Awareness/strategy level; no hands-on builds. Team membership $235–265 per member. | D7: https://medicalaffairs.org/membership/
A8: CELforPharma | B8: Pharma training company (EU) | C8: Belgian, since 2005. 2-day in-person 'AI for Medical Affairs' in Brussels, EUR 3,370 (early bird EUR 2,970), max 20; includes Colab coding and insight-analysis workshops. Attendance certificate only; CET only; little PV/off-label content. | D8: https://www.celforpharma.com/course/ai-medical-affairs-course
A9: Eularis | B9: AI consultancy (pharma-wide) | C9: UK-run, founder-led. Exec masterclass, function tracks and AI Enablement Institute (business-unit licence, partner places capped at 5). Testimonials from Roche, Pfizer, Novo Nordisk, Takeda. No prices, no MSL focus, no builds or credential. | D9: https://eularis.com/ai-training-in-pharma/
A10: Medical Affairs Value / MSL Mastery | B10: Boutique MSL trainer | C10: Founder-led (Phoenix, AZ); paid AI training sold via MSL Mastery. 60-minute 'AI Agent-in-a-Box' live build in Copilot/ChatGPT plus customized team modules; claims 500+ trained in 2025. Nearest in content; no compliance, assessment, credential or public price. | D10: https://www.mslmastery.com/training
A11: Inizio MSL Interact (HCP Interact) | B11: Adjacent: AI that trains MSLs | C11: Inizio (CD&R-backed, ~10,000 staff). LLM HCP avatars for engagement rehearsal inside iON AI platform (launched Mar 2025). Does not teach MSLs to use AI; strong on dashboards and TA customization. No pricing or named clients. | D11: https://inizio.com/insights/elevate-msl-performance/
A12: Section | B12: Horizontal AI upskilling benchmark | C12: US AI-proficiency platform: free tier, $41–82/mo individual, $750/seat small teams; Credly badge, SSO/LMS, admin dashboard, quantified case studies (Logitech, Horizon Media). Not pharma-specific; no compliance content. | D12: https://www.sectionai.com/pricing

Sheet Market
A1: Market signals
A2: Opened and checked Oct 2026. Gaps marked for the founder to supply.
A4: Signal | B4: Figure | C4: Why it matters | D4: Source
A5: US MSL headcount | B5: No published national count found. MSL Society 2022 US salary survey had 1,384 respondents incl. 1,032 MSLs (a floor, not a total). GAP: founder to supply a sizing source. | C5: Sets the ceiling for the B2C and seat-licence revenue; must be sourced before any TAM claim. | D5: https://themsljournal.com/article/msl-salary-and-compensation-2022-data-from-medical-science-liaisons-and-msl-management-roles-in-the-united-states/
A6: AI adoption in medical affairs (2026) | B6: BP Logix benchmark, 79 respondents Feb–May 2026: literature monitoring the top use case (44% implemented, 38% want to expand); validation/accuracy the top barrier; 49% manually review every AI output. | C6: Demand is real but practice lags belief; the review-gate and verification skills the curriculum teaches map to the stated barrier. Small, non-representative sample. | D6: https://www.bplogix.com/2026-med-affairs-survey
A7: KOLs already use AI before meeting MSLs | B7: Veeva KOL survey (75 KOLs, Apr 2026): 40% of HCPs would ask AI before contacting an MSL; 88% of KOLs expect MSL interactions to change. | C7: The MSL role is being reshaped by AI on the customer side, which raises the urgency for MSLs to work fluently with AI. | D7: https://www.veeva.com/eu/resources/how-ai-is-changing-kol-behavior/
A8: US corporate training spend | B8: Training magazine 2025: US training spend $102.8bn (+4.9%); $874 per learner on average; large companies $468 per learner; 40 hours per employee. | C8: A typical per-learner budget is under $1,000 a year, so enterprise seat pricing above that needs a medical-affairs-specific budget line, not general L&D. | D8: https://trainingmag.com/2025-training-industry-report/
A9: Price benchmark — deep MA course | B9: CELforPharma AI for Medical Affairs: EUR 3,370 (early bird EUR 2,970) for a 2-day in-person course in Brussels. | C9: Upper anchor for a deep, live, medical-affairs AI course. | D9: https://www.celforpharma.com/course/ai-medical-affairs-course
A10: Price benchmark — horizontal AI upskilling | B10: Section: free Basic tier; On Demand $41/mo and Unlimited $82/mo billed annually; small teams $750/seat. | C10: Lower anchor: generic AI proficiency is cheap, so MSL-specific depth and compliance must justify the premium. | D10: https://www.sectionai.com/pricing

Sheet Viability
A1: Viability — business criteria (1–5)
A2: Reviewer judgement from the evidence in this workbook; edit yellow scores. Verdict: GREEN ≥ 75% of max, AMBER 55–74%, RED < 55%.
A4: Criterion | B4: Score (1–5) | C4: Reason
A5: Problem urgency | B5: 4 | C5: KOLs already use AI before MSL meetings (Veeva, Apr 2026) and medical affairs reports belief outrunning practice (BP Logix 2026).
A6: Willingness to pay (evidence) | B6: 3 | C6: Buyers already pay $450–500 for 4 hours (MSL Society), $2,399 (ACMA) and EUR 3,370 (CELforPharma); average L&D spend is only $874 per learner.
A7: Market size clarity | B7: 2 | C7: No published US MSL headcount found; only survey samples (1,032 MSLs in 2022). Must be sourced before pitching.
A8: Differentiation | B8: 4 | C8: No competitor scores 2+ on vibe coding, automation with review gates, PV routing and performance assessment together.
A9: Incumbent threat (5 = low) | B9: 2 | C9: MSL Society owns the audience; ACMA already added agent-building to BCMAS (Nov 2025); MAPS has 18,000 members and is producing AI content weekly.
A10: Founder–market fit | B10: 3 | C10: Strong research, AI-build and pharmacy background; no practising MSL tenure, so co-faculty with field MSL experience is needed. Founder to confirm.
A11: Time to MVP | B11: 4 | C11: Self-paced core plus prompt/agent library can ship in months with off-the-shelf LMS.
A12: Enterprise procurement friction | B12: 2 | C12: Pharma vendor onboarding (InfoSec questionnaire, MSA) and IT restrictions on AI tools slow team sales.
A13: Credential defensibility | B13: 2 | C13: A credential only becomes a moat through accreditation (IACET/ACCME partner) or association endorsement; neither exists yet.
A14: Scalability and margin | B14: 4 | C14: Self-paced core keeps margin high; live cohorts and graded builds are the cost drivers.
A15: Total | B15: =SUM(B5:B14)&" of "&COUNT(B5:B14)*5
A16: Share of maximum | B16: =SUM(B5:B14)/(COUNT(B5:B14)*5)
A17: Verdict | B17: =IF(B16>=0.75,"GREEN",IF(B16>=0.55,"AMBER","RED"))

Sheet Roadmap ceiling
A1: Roadmap ceiling — realistic score after each phase
A2: Reviewer's estimate of what each phase can earn. Evidence-only criteria (credential, CE, outcomes, SOC 2, clients, audience) cannot be designed in.
A4: ID | B4: Criterion | C4: Weight | D4: Gate | E4: Evidence-only? | F4: Phase 1: MVP (months 0–4) | G4: Phase 2: Pilot with 1–2 teams (4–8) | H4: Phase 3: Certified, national (8–12)
A5: =Rubric!A5 | B5: =Rubric!C5 | C5: =Rubric!E5 | D5: =Rubric!F5 | F5: 3 | G5: 3 | H5: 3
A6: =Rubric!A6 | B6: =Rubric!C6 | C6: =Rubric!E6 | D6: =Rubric!F6 | F6: 2 | G6: 3 | H6: 3
A7: =Rubric!A7 | B7: =Rubric!C7 | C7: =Rubric!E7 | D7: =Rubric!F7 | F7: 2 | G7: 3 | H7: 3
A8: =Rubric!A8 | B8: =Rubric!C8 | C8: =Rubric!E8 | D8: =Rubric!F8 | F8: 1 | G8: 2 | H8: 3
A9: =Rubric!A9 | B9: =Rubric!C9 | C9: =Rubric!E9 | D9: =Rubric!F9 | F9: 3 | G9: 3 | H9: 3
A10: =Rubric!A10 | B10: =Rubric!C10 | C10: =Rubric!E10 | D10: =Rubric!F10 | F10: 1 | G10: 2 | H10: 3
A11: =Rubric!A11 | B11: =Rubric!C11 | C11: =Rubric!E11 | D11: =Rubric!F11 | F11: 1 | G11: 2 | H11: 3
A12: =Rubric!A12 | B12: =Rubric!C12 | C12: =Rubric!E12 | D12: =Rubric!F12 | F12: 2 | G12: 3 | H12: 3
A13: =Rubric!A13 | B13: =Rubric!C13 | C13: =Rubric!E13 | D13: =Rubric!F13 | F13: 1 | G13: 2 | H13: 3
A14: =Rubric!A14 | B14: =Rubric!C14 | C14: =Rubric!E14 | D14: =Rubric!F14 | F14: 2 | G14: 3 | H14: 3
A15: =Rubric!A15 | B15: =Rubric!C15 | C15: =Rubric!E15 | D15: =Rubric!F15 | F15: 2 | G15: 3 | H15: 3
A16: =Rubric!A16 | B16: =Rubric!C16 | C16: =Rubric!E16 | D16: =Rubric!F16 | F16: 2 | G16: 3 | H16: 3
... A24: =Rubric!A24 | B24: =Rubric!C24 | C24: =Rubric!E24 | D24: =Rubric!F24 | F24: 2 | G24: 3 | H24: 3
A25: =Rubric!A25 | B25: =Rubric!C25 | C25: =Rubric!E25 | D25: =Rubric!F25 | E25: Y | F25: 1 | G25: 1 | H25: 2
A26: =Rubric!A26 | B26: =Rubric!C26 | C26: =Rubric!E26 | D26: =Rubric!F26 | E26: Y | F26: 0 | G26: 1 | H26: 2
A27: =Rubric!A27 | B27: =Rubric!C27 | C27: =Rubric!E27 | D27: =Rubric!F27 | F27: 2 | G27: 3 | H27: 3
A28: =Rubric!A28 | B28: =Rubric!C28 | C28: =Rubric!E28 | D28: =Rubric!F28 | F28: 2 | G28: 3 | H28: 3
A29: =Rubric!A29 | B29: =Rubric!C29 | C29: =Rubric!E29 | D29: =Rubric!F29 | E29: Y | F29: 0 | G29: 1 | H29: 3
A30: =Rubric!A30 | B30: =Rubric!C30 | C30: =Rubric!E30 | D30: =Rubric!F30 | F30: 1 | G30: 2 | H30: 3
A31: =Rubric!A31 | B31: =Rubric!C31 | C31: =Rubric!E31 | D31: =Rubric!F31 | F31: 2 | G31: 3 | H31: 3
A32: =Rubric!A32 | B32: =Rubric!C32 | C32: =Rubric!E32 | D32: =Rubric!F32 | F32: 2 | G32: 3 | H32: 3
A33: =Rubric!A33 | B33: =Rubric!C33 | C33: =Rubric!E33 | D33: =Rubric!F33 | F33: 2 | G33: 3 | H33: 3
A34: =Rubric!A34 | B34: =Rubric!C34 | C34: =Rubric!E34 | D34: =Rubric!F34 | F34: 1 | G34: 3 | H34: 3
A35: =Rubric!A35 | B35: =Rubric!C35 | C35: =Rubric!E35 | D35: =Rubric!F35 | E35: Y | F35: 1 | G35: 2 | H35: 2
A36: =Rubric!A36 | B36: =Rubric!C36 | C36: =Rubric!E36 | D36: =Rubric!F36 | F36: 0 | G36: 1 | H36: 3
A37: =Rubric!A37 | B37: =Rubric!C37 | C37: =Rubric!E37 | D37: =Rubric!F37 | F37: 1 | G37: 2 | H37: 3
A38: =Rubric!A38 | B38: =Rubric!C38 | C38: =Rubric!E38 | D38: =Rubric!F38 | E38: Y | F38: 0 | G38: 1 | H38: 2
A39: =Rubric!A39 | B39: =Rubric!C39 | C39: =Rubric!E39 | D39: =Rubric!F39 | F39: 3 | G39: 3 | H39: 3
A40: =Rubric!A40 | B40: =Rubric!C40 | C40: =Rubric!E40 | D40: =Rubric!F40 | F40: 2 | G40: 3 | H40: 3
A41: =Rubric!A41 | B41: =Rubric!C41 | C41: =Rubric!E41 | D41: =Rubric!F41 | F41: 1 | G41: 2 | H41: 3
A42: =Rubric!A42 | B42: =Rubric!C42 | C42: =Rubric!E42 | D42: =Rubric!F42 | E42: Y | F42: 0 | G42: 1 | H42: 2
A43: =Rubric!A43 | B43: =Rubric!C43 | C43: =Rubric!E43 | D43: =Rubric!F43 | F43: 3 | G43: 3 | H43: 3
A44: =Rubric!A44 | B44: =Rubric!C44 | C44: =Rubric!E44 | D44: =Rubric!F44 | F44: 3 | G44: 3 | H44: 3
A45: =Rubric!A45 | B45: =Rubric!C45 | C45: =Rubric!E45 | D45: =Rubric!F45 | F45: 2 | G45: 3 | H45: 3
A46: =Rubric!A46 | B46: =Rubric!C46 | C46: =Rubric!E46 | D46: =Rubric!F46 | F46: 3 | G46: 3 | H46: 3
B48: Overall weighted score (Summary domain weights) | F48: =(Summary!$B$5*SUMPRODUCT((Rubric!$B$5:$B$46=Summary!$A$5)*$C$5:$C$46*F5:F46)/(SUMPRODUCT((Rubric!$B$5:$B$46=Summary!$A$5)*$C$5:$C$46)*3)+Summary!$B$6*SUMPRODUCT((Rubric!$B$5:$B$46=Summary!$A$6)*$C$5:$C$46*F5:F46)/(SUMPRODUCT((Rubric!$B$5:$B$46=Summary!$A$6)*$C$5:$C$46)*3)+Summary!$B$7*SUMPRODUCT((Rubric!$B$5:$B$46=Summary!$A$7)*$C$5:$C$46*F5:F46)/(SUMPRODUCT((Rubric!$B$5:$B$46=Summary!$A$7)*$C$5:$C$46)*3)+Summary!$B$8*SUMPRODUCT((Rubric!$B$5:$B$46=Summary!$A$8)*$C$5:$C$46*F5:F46)/(SUMPRODUCT((Rubric!$B$5:$B$46=Summary!$A$8)*$C$5:$C$46)*3)+Summary!$B$9*SUMPRODUCT((Rubric!$B$5:$B$46=Summary!$A$9)*$C$5:$C$46*F5:F46)/(SUMPRODUCT((Rubric!$B$5:$B$46=Summary!$A$9)*$C$5:$C$46)*3)+Summary!$B$10*SUMPRODUCT((Rubric!$B$5:$B$46=Summary!$A$10)*$C$5:$C$46*F5:F46)/(SUMPRODUCT((Rubric!$B$5:$B$46=Summary!$A$10)*$C$5:$C$46)*3)+Summary!$B$11*SUMPRODUCT((Rubric!$B$5:$B$46=Summary!$A$11)*$C$5:$C$46*F5:F46)/(SUMPRODUCT((Rubric!$B$5:$B$46=Summary!$A$11)*$C$5:$C$46)*3)+Summary!$B$12*SUMPRODUCT((Rubric!$B$5:$B$46=Summary!$A$12)*$C$5:$C$46*F5:F46)/(SUMPRODUCT((Rubric!$B$5:$B$46=Summary!$A$12)*$C$5:$C$46)*3)+Summary!$B$13*SUMPRODUCT((Rubric!$B$5:$B$46=Summary!$A$13)*$C$5:$C$46*F5:F46)/(SUMPRODUCT((Rubric!$B$5:$B$46=Summary!$A$13)*$C$5:$C$46)*3)+Summary!$B$14*SUMPRODUCT((Rubric!$B$5:$B$46=Summary!$A$14)*$C$5:$C$46*F5:F46)/(SUMPRODUCT((Rubric!$B$5:$B$46=Summary!$A$14)*$C$5:$C$46)*3))/SUM(Summary!$B$5:$B$14) | G48: =(Summary!$B$5*SUMPRODUCT((Rubric!$B$5:$B$46=Summary!$A$5)*$C$5:$C$46*G5:G46)/(SUMPRODUCT((Rubric!$B$5:$B$46=Summary!$A$5)*$C$5:$C$46)*3)+Summary!$B$6*SUMPRODUCT((Rubric!$B$5:$B$46=Summary!$A$6)*$C$5:$C$46*G5:G46)/(SUMPRODUCT((Rubric!$B$5:$B$46=Summary!$A$6)*$C$5:$C$46)*3)+Summary!$B$7*SUMPRODUCT((Rubric!$B$5:$B$46=Summary!$A$7)*$C$5:$C$46*G5:G46)/(SUMPRODUCT((Rubric!$B$5:$B$46=Summary!$A$7)*$C$5:$C$46)*3)+Summary!$B$8*SUMPRODUCT((Rubric!$B$5:$B$46=Summary!$A$8)*$C$5:$C$46*G5:G46)/(SUMPRODUCT((Rubric!$B$5:$B$46=Summary!$A$8)*$C$5:$C$46)*3)+Summary!$B$9*SUMPRODUCT((Rubric!$B$5:$B$46=Summary!$A$9)*$C$5:$C$46*G5:G46)/(SUMPRODUCT((Rubric!$B$5:$B$46=Summary!$A$9)*$C$5:$C$46)*3)+Summary!$B$10*SUMPRODUCT((Rubric!$B$5:$B$46=Summary!$A$10)*$C$5:$C$46*G5:G46)/(SUMPRODUCT((Rubric!$B$5:$B$46=Summary!$A$10)*$C$5:$C$46)*3)+Summary!$B$11*SUMPRODUCT((Rubric!$B$5:$B$46=Summary!$A$11)*$C$5:$C$46*G5:G46)/(SUMPRODUCT((Rubric!$B$5:$B$46=Summary!$A$11)*$C$5:$C$46)*3)+Summary!$B$12*SUMPRODUCT((Rubric!$B$5:$B$46=Summary!$A$12)*$C$5:$C$46*G5:G46)/(SUMPRODUCT((Rubric!$B$5:$B$46=Summary!$A$12)*$C$5:$C$46)*3)+Summary!$B$13*SUMPRODUCT((Rubric!$B$5:$B$46=Summary!$A$13)*$C$5:$C$46*G5:G46)/(SUMPRODUCT((Rubric!$B$5:$B$46=Summary!$A$13)*$C$5:$C$46)*3)+Summary!$B$14*SUMPRODUCT((Rubric!$B$5:$B$46=Summary!$A$14)*$C$5:$C$46*G5:G46)/(SUMPRODUCT((Rubric!$B$5:$B$46=Summary!$A$14)*$C$5:$C$46)*3))/SUM(Summary!$B$5:$B$14) | H48: =(Summary!$B$5*SUMPRODUCT((Rubric!$B$5:$B$46=Summary!$A$5)*$C$5:$C$46*H5:H46)/(SUMPRODUCT((Rubric!$B$5:$B$46=Summary!$A$5)*$C$5:$C$46)*3)+Summary!$B$6*SUMPRODUCT((Rubric!$B$5:$B$46=Summary!$A$6)*$C$5:$C$46*H5:H46)/(SUMPRODUCT((Rubric!$B$5:$B$46=Summary!$A$6)*$C$5:$C$46)*3)+Summary!$B$7*SUMPRODUCT((Rubric!$B$5:$B$46=Summary!$A$7)*$C$5:$C$46*H5:H46)/(SUMPRODUCT((Rubric!$B$5:$B$46=Summary!$A$7)*$C$5:$C$46)*3)+Summary!$B$8*SUMPRODUCT((Rubric!$B$5:$B$46=Summary!$A$8)*$C$5:$C$46*H5:H46)/(SUMPRODUCT((Rubric!$B$5:$B$46=Summary!$A$8)*$C$5:$C$46)*3)+Summary!$B$9*SUMPRODUCT((Rubric!$B$5:$B$46=Summary!$A$9)*$C$5:$C$46*H5:H46)/(SUMPRODUCT((Rubric!$B$5:$B$46=Summary!$A$9)*$C$5:$C$46)*3)+Summary!$B$10*SUMPRODUCT((Rubric!$B$5:$B$46=Summary!$A$10)*$C$5:$C$46*H5:H46)/(SUMPRODUCT((Rubric!$B$5:$B$46=Summary!$A$10)*$C$5:$C$46)*3)+Summary!$B$11*SUMPRODUCT((Rubric!$B$5:$B$46=Summary!$A$11)*$C$5:$C$46*H5:H46)/(SUMPRODUCT((Rubric!$B$5:$B$46=Summary!$A$11)*$C$5:$C$46)*3)+Summary!$B$12*SUMPRODUCT((Rubric!$B$5:$B$46=Summary!$A$12)*$C$5:$C$46*H5:H46)/(SUMPRODUCT((Rubric!$B$5:$B$46=Summary!$A$12)*$C$5:$C$46)*3)+Summary!$B$13*SUMPRODUCT((Rubric!$B$5:$B$46=Summary!$A$13)*$C$5:$C$46*H5:H46)/(SUMPRODUCT((Rubric!$B$5:$B$46=Summary!$A$13)*$C$5:$C$46)*3)+Summary!$B$14*SUMPRODUCT((Rubric!$B$5:$B$46=Summary!$A$14)*$C$5:$C$46*H5:H46)/(SUMPRODUCT((Rubric!$B$5:$B$46=Summary!$A$14)*$C$5:$C$46)*3))/SUM(Summary!$B$5:$B$14)
B49: Gate failures | F49: =COUNTIFS($D$5:$D$46,"Y",F5:F46,"<2") | G49: =COUNTIFS($D$5:$D$46,"Y",G5:G46,"<2") | H49: =COUNTIFS($D$5:$D$46,"Y",H5:H46,"<2")
...
